Workbook

Sheet Output 1
B2: Output 1
B3: BigTechCompany
B4: Quarterly Financial Overview
B6: Instructions:
B7: Using the income statement, balance sheet and cash flow statements, populate the quarterly financial information for Stargaze.
B8: Calculate the quarter-over-quarter growth for revenue, operating income (EBITDA) and net income per share.
B9: Then, calculate the financial metrics.
B10: Ensure that your number formatting is consistent with the formatting in column D.
B11: Once finished, copy this table on page 2 of your PowerPoint template.
B14: BigTech Company | C14: Q1 | D14: Q2 | E14: Q3 | F14: Q4 | G14: Q1 | H14: Q2 | I14: Q3 | J14: Q4 | K14: Q1
B15: ($ in thousands) | C15: 2021 | D15: 2021 | E15: 2021 | F15: 2021 | G15: 2022 | H15: 2022 | I15: 2022 | J15: 2022 | K15: 2023
B16: Revenues | C16: ='Income Statement'!F9 -> 501429.74 | D16: ='Income Statement'!G9 -> 513924.39 | E16: ='Income Statement'!H9 -> 523842.69 | F16: ='Income Statement'!I9 -> 539652.26 | G16: ='Income Statement'!K9 -> 550743.69 | H16: ='Income Statement'!L9 -> 557909.87 | I16: ='Income Statement'!M9 -> 554791.23 | J16: ='Income Statement'!N9 -> 549643.71 | K16: ='Income Statement'!P9 -> 571305.21 | M16: ='Income Statement'!Q9 -> 0
B17: Quarterly Growth | D17: =(D16/C16)-1 -> 0.024918047 | E17: =(E16/D16)-1 -> 0.019299142 | F17: =(F16/E16)-1 -> 0.030179995 | G17: =(G16/F16)-1 -> 0.020552921 | H17: =(H16/G16)-1 -> 0.013011824 | I17: =(I16/H16)-1 -> -0.0055898635 | J17: =(J16/I16)-1 -> -0.009278301 | K17: =(K16/J16)-1 -> 0.039410075
B19: Operating Income (EBITDA) | C19: ='Income Statement'!F14 -> 137189.92 | D19: ='Income Statement'!G14 -> 129334.1 | E19: ='Income Statement'!H14 -> 122867.71 | F19: ='Income Statement'!I14 -> 44223.9 | G19: ='Income Statement'!K14 -> 138013.82 | H19: ='Income Statement'!L14 -> 110479.81 | I19: ='Income Statement'!M14 -> 107311.26 | J19: ='Income Statement'!N14 -> 38493.28 | K19: ='Income Statement'!P14 -> 120002.19
B20: Quarterly Growth | D20: =(D19/C19)-1 -> -0.05726237 | E20: =(E19/D19)-1 -> -0.049997564 | F20: =(F19/E19)-1 -> -0.64006898 | G20: =(G19/F19)-1 -> 2.1207971 | H20: =(H19/G19)-1 -> -0.19950183 | I20: =(I19/H19)-1 -> -0.028679901 | J20: =(J19/I19)-1 -> -0.64129319 | K20: =(K19/J19)-1 -> 2.1174841
B22: Net Income | C22: ='Income Statement'!F20 -> 119470.05 | D22: ='Income Statement'!G20 -> 94710.91 | E22: ='Income Statement'!H20 -> 101434.97 | F22: ='Income Statement'!I20 -> 42520.03 | G22: ='Income Statement'!K20 -> 111821.29 | H22: ='Income Statement'!L20 -> 100866.57 | I22: ='Income Statement'!M20 -> 97876.94 | J22: ='Income Statement'!N20 -> 3869.88 | K22: ='Income Statement'!P20 -> 102018.79
B23: Quarterly Growth | D23: =(D22/C22)-1 -> -0.2072414 | E23: =(E22/D22)-1 -> 0.070995622 | F23: =(F22/E22)-1 -> -0.58081488 | G23: =(G22/F22)-1 -> 1.6298497 | H23: =(H22/G22)-1 -> -0.097966318 | I23: =(I22/H22)-1 -> -0.029639453 | J23: =(J22/I22)-1 -> -0.96046178 | K23: =(K22/J22)-1 -> 25.362261
B24: Net Income per Share | C24: ='Income Statement'!F22 -> 3.8506827 | D24: ='Income Statement'!G22 -> 3.0531096 | E24: ='Income Statement'!H22 -> 3.2726807 | F24: ='Income Statement'!I22 -> 1.3697431 | G24: ='Income Statement'!K22 -> 3.5966709 | H24: ='Income Statement'!L22 -> 3.2413189 | I24: ='Income Statement'!M22 -> 3.1429785 | J24: ='Income Statement'!N22 -> 0.1241779 | K24: ='Income Statement'!P22 -> 3.2732866
B26: Non GAAP Free Cash Flow (FCF) | C26: ='Cash Flows'!H51 -> 48415.5 | D26: ='Cash Flows'!I51 -> -12252.73 | E26: ='Cash Flows'!J51 -> -7437.64 | F26: ='Cash Flows'!K51 -> -39847.71 | G26: ='Cash Flows'!M51 -> 56117.67 | H26: ='Cash Flows'!N51 -> 891.24 | I26: ='Cash Flows'!O51 -> 33029.5 | J26: ='Cash Flows'!P51 -> 23258.55 | K26: ='Cash Flows'!R51 -> 56812.07
B28: Financial Metrics | C28: Q1 2021 | D28: Q2 2021 | E28: Q3 2021 | F28: Q4 2021 | G28: Q1 2022 | H28: Q2 2022 | I28: Q3 2022 | J28: Q4 2022 | K28: Q1 2023
B29: EBITDA Margin | C29: =C19/C16 -> 0.27359749 | D29: =D19/D16 -> 0.25165978 | E29: =E19/E16 -> 0.23455078 | F29: =F19/F16 -> 0.081948883 | G29: =G19/G16 -> 0.25059537 | H29: =H19/H16 -> 0.19802448 | I29: =I19/I16 -> 0.19342638 | J29: =J19/J16 -> 0.070033149 | K29: =K19/K16 -> 0.21004918 | M29: Hint: EBITDA margin is calculated as EBITDA divided by revenue.
B30: Net Income Margin | C30: =C22/C16 -> 0.2382588 | D30: =D22/D16 -> 0.18428958 | E30: =E22/E16 -> 0.19363632 | F30: =F22/F16 -> 0.078791535 | G30: =G22/G16 -> 0.2030369 | H30: =H22/H16 -> 0.18079366 | I30: =I22/I16 -> 0.17642121 | J30: =J22/J16 -> 0.0070407064 | K30: =K22/K16 -> 0.17857142
B31: FCF per Diluted Share | C31: =C26/'Income Statement'!F26 -> 1.5179714 | D31: =D26/'Income Statement'!G26 -> -0.38459206 | E31: =E26/'Income Statement'!H26 -> -0.23355938 | F31: =F26/'Income Statement'!I26 -> -1.2489233 | G31: =G26/'Income Statement'!K26 -> 1.7697777 | H31: =H26/'Income Statement'!L26 -> 0.028282712 | I31: =I26/'Income Statement'!M26 -> 1.0477546 | J31: =J26/'Income Statement'!N26 -> 0.73567084 | K31: =K26/'Income Statement'!P26 -> 1.7939224 | M31: Hint: divide FCF by diluted shares.

Sheet Output 2
B2: Output 2
B3: BigTechCompany
B4: Customer Trends
B6: Instructions:
B7: Using the Customer Data tab, populate the quarterly information on Stargaze customers.
B8: Ensure that your formatting is consistent across the table. Your formatting should match that of column D.
B9: Once finished, copy your table into page 3 of the PowerPoint presentation.
B12: Customer Trends | C12: Q1 | D12: Q2 | E12: Q3 | F12: Q4 | G12: Q1 | H12: Q2 | I12: Q3 | J12: Q4 | K12: Q1
B13: #s in thousands | C13: 2021 | D13: 2021 | E13: 2021 | F13: 2021 | G13: 2022 | H13: 2022 | I13: 2022 | J13: 2022 | K13: 2023
B15: Cost of Subscription (Quarterly) | C15: ='Customer Data'!C7 -> 33 | D15: ='Customer Data'!D7 -> 33 | E15: ='Customer Data'!E7 -> 33 | F15: ='Customer Data'!F7 -> 33 | G15: ='Customer Data'!G7 -> 34 | H15: ='Customer Data'!H7 -> 34 | I15: ='Customer Data'!I7 -> 34 | J15: ='Customer Data'!J7 -> 34 | K15: ='Customer Data'!K7 -> 34
B17: Number of Users (Beginning of Period) | C17: ='Customer Data'!C9 -> 15194.841 | D17: ='Customer Data'!D9 -> 15573.466 | E17: ='Customer Data'!E9 -> 15874.021 | F17: ='Customer Data'!F9 -> 16353.099 | G17: ='Customer Data'!G9 -> 16198.344 | H17: ='Customer Data'!H9 -> 16409.114 | I17: ='Customer Data'!I9 -> 16317.389 | J17: ='Customer Data'!J9 -> 16165.991 | K17: ='Customer Data'!K9 -> 16803.094
B18: Customer Attrition | C18: ='Customer Data'!C11 -> 89 | D18: ='Customer Data'!D11 -> 200 | E18: ='Customer Data'!E11 -> 204 | F18: ='Customer Data'!F11 -> 444 | G18: ='Customer Data'!G11 -> 2446 | H18: ='Customer Data'!H11 -> 5000 | I18: ='Customer Data'!I11 -> 1655 | J18: ='Customer Data'!J11 -> 1244 | K18: ='Customer Data'!K11 -> 322 | M18: Hint: Customer attrition is the number of customers who canceled their service.
B19: New Users | C19: ='Customer Data'!C10 -> 467.62576 | D19: ='Customer Data'!D10 -> 500.55455 | E19: ='Customer Data'!E10 -> 683.07788 | F19: ='Customer Data'!F10 -> 289.24504 | G19: ='Customer Data'!G10 -> 2656.77 | H19: ='Customer Data'!H10 -> 4908.2753 | I19: ='Customer Data'!I10 -> 1503.6024 | J19: ='Customer Data'!J10 -> 1881.1029 | K19: ='Customer Data'!K10 -> 1964.9056
B20: Number of Users (End of Period) | C20: ='Customer Data'!C12 -> 15573.466 | D20: ='Customer Data'!D12 -> 15874.021 | E20: ='Customer Data'!E12 -> 16353.099 | F20: ='Customer Data'!F12 -> 16198.344 | G20: ='Customer Data'!G12 -> 16409.114 | H20: ='Customer Data'!H12 -> 16317.389 | I20: ='Customer Data'!I12 -> 16165.991 | J20: ='Customer Data'!J12 -> 16803.094 | K20: ='Customer Data'!K12 -> 18446
B21: Change in # of Users | D21: =(D20/C20)-1 -> 0.019299142 | E21: =(E20/D20)-1 -> 0.030179995 | F21: =(F20/E20)-1 -> -0.0094633419 | G21: =(G20/F20)-1 -> 0.013011824 | H21: =(H20/G20)-1 -> -0.0055898635 | I21: =(I20/H20)-1 -> -0.009278301 | J21: =(J20/I20)-1 -> 0.039410075 | K21: =(K20/J20)-1 -> 0.09777399
B23: Net Change in Customers | C23: =C19-C18 -> 378.62576 | D23: =D19-D18 -> 300.55455 | E23: =E19-E18 -> 479.07788 | F23: =F19-F18 -> -154.75496 | G23: =G19-G18 -> 210.77 | H23: =H19-H18 -> -91.724706 | I23: =I19-I18 -> -151.39765 | J23: =J19-J18 -> 637.10294 | K23: =K19-K18 -> 1642.9056 | M23: Hint: This is calculated by taking the number of new users minus the number of customers who canceled their services.
B24: Churn Rate | C24: =C18/C17 -> 0.0058572513 | D24: =D18/D17 -> 0.012842356 | E24: =E18/E17 -> 0.012851186 | F24: =F18/F17 -> 0.027150817 | G24: =G18/G17 -> 0.15100309 | H24: =H18/H17 -> 0.30470872 | I24: =I18/I17 -> 0.10142554 | J24: =J18/J17 -> 0.076951667 | K24: =K18/K17 -> 0.019163137 | M24: Hint: Churn rate is calculated by taking the number of customers lost in a period divided by the number of total customers in the previous period.

Sheet Output 3
B3: Output 3
B4: BigTechCompany
B5: Annual Projections
B7: Instructions:
B8: Populate the historical financial information from the income statement, balance sheet and statement of cash flows.
B9: For the 2023E figures, you will need to use annualized figures. To do this, multiply Q1 2023 metrics by 4.
B10: For the 2024E figures, the company is assuming the following:
B11: Revenues increase by 15%
B12: Operating income increases by 10%
B13: Net income increases by 8%
B14: FCF decreases by 2%
B15: Share count remains the same
... B17: Once you have finished populating the table, check to make sure your formatting matches column D. Then copy the table into the PowerPoint presentation.
C21: FY | D21: FY | E21: FY | F21: FY | G21: FY | H21: 2020-2024E
B22: Financial Highlights | C22: 2020 | D22: 2021 | E22: 2022 | F22: 2023E | G22: 2024E | H22: CAGR | J22: < Hint: CAGR is an abbrevation for Compound Annual Growth Rate.
B23: Revenues | C23: 1999444 | D23: 2078849.1 | E23: ='Income Statement'!O9 -> 2213088.5 | F23: ='Income Statement'!P9*4 -> 2285220.8 | G23: =F23*(1+0.15) -> 2628004 | H23: =(G23/C23)^(1/4)-1 -> 0.070728081 | J23: Learn how to Calculate CAGR
B24: Annual Growth | D24: =(D23/C23)-1 -> 0.03971358 | E24: =(E23/D23)-1 -> 0.064573913 | F24: =(F23/E23)-1 -> 0.032593518 | G24: =(G23/F23)-1 -> 0.15
B25: Operating Income (EBITDA) | C25: 371461.44 | D25: 433615.63 | E25: ='Income Statement'!O14 -> 394298.17 | F25: ='Income Statement'!P14*4 -> 480008.76 | G25: =F25*(1+0.1) -> 528009.64 | H25: =(G25/C25)^(1/4)-1 -> 0.091897892
B26: Annual Growth | D26: =(D25/C25)-1 -> 0.1673234 | E26: =(E25/D25)-1 -> -0.09067353 | F26: =(F25/E25)-1 -> 0.21737506 | G26: =(G25/F25)-1 -> 0.1
B27: Net Income | C27: 247640.96 | D27: 358135.96 | E27: ='Income Statement'!O20 -> 314434.68 | F27: ='Income Statement'!P20*4 -> 408075.14 | G27: =F27*(1+0.08) -> 440721.15 | H27: =(G27/C27)^(1/4)-1 -> 0.15500896
B28: Annual Growth | D28: =(D27/C27)-1 -> 0.44619032 | E28: =(E27/D27)-1 -> -0.12202427 | F28: =(F27/E27)-1 -> 0.29780577 | G28: =(G27/F27)-1 -> 0.08
B29: Net Income per Share | C29: 12.11 | D29: 11.546216 | E29: ='Income Statement'!O22 -> 10.105146 | F29: ='Income Statement'!P22*4 -> 13.093146 | G29: =G27/'Income Statement'!P25 -> 14.140598 | H29: =(G29/C29)^(1/4)-1 -> 0.039515356
B30: Non GAAP Free Cash Flow (FCF) | C30: 755 | D30: ='Cash Flows'!L51 -> -11122.58 | E30: ='Cash Flows'!Q51 -> 113296.96 | F30: ='Cash Flows'!R51*4 -> 227248.28 | G30: =F30*(0.98) -> 222703.31 | H30: =(G30/C30)^(1/4)-1 -> 3.1442403
B32: Financial Metrics
B33: EBITDA Margin | C33: =C25/C23 -> 0.18578237 | D33: =D25/D23 -> 0.20858447 | E33: =E25/E23 -> 0.17816647 | F33: =F25/F23 -> 0.21004918 | G33: =G25/G23 -> 0.20091661
B34: Net Income Margin | C34: =C27/C23 -> 0.12385491 | D34: =D27/D23 -> 0.17227607 | E34: =E27/E23 -> 0.14207958 | F34: =F27/F23 -> 0.17857142 | G34: =G27/G23 -> 0.16770186
B35: Debt/EBITDA | C35: 2.7x | D35: 2.371951 | E35: ='Balance Sheet'!N27/'Output 3'!E25 -> 2.5481105 | F35: ='Balance Sheet'!O27/'Output 3'!F25 -> 2.0471659 | G35: ='Balance Sheet'!O27/'Output 3'!G25 -> 1.8610599
B36: FCF per Diluted Share | C36: =C30/'Income Statement'!F26 -> 0.023671518 | D36: =D30/'Income Statement'!J26 -> -0.34860848 | E36: =E30/'Income Statement'!O26 -> 3.583597 | F36: =F30/'Income Statement'!P26 -> 7.1756897 | G36: =G30/'Income Statement'!P26 -> 7.0321759

Sheet Income Statement
A1: BigTechCompany
A2: Consolidated Statements of Operations
A3: (unaudited)
A4: (in thousands, except per share data)
F5: Three Months Ended | J5: Twelve Months Ended | K5: Three Months Ended | O5: Twelve Months Ended | P5: Three Months Ended
F6: March 31, | G6: June 30, | H6: September 30, | I6: December 31, | J6: December 31, | K6: March 31, | L6: June 30, | M6: September 30, | N6: December 31, | O6: December 31, | P6: March 31,
F7: 2021 | G7: 2021 | H7: 2021 | I7: 2021 | J7: 2021 | K7: 2022 | L7: 2022 | M7: 2022 | N7: 2022 | O7: 2022 | P7: 2023
A9: Revenues | F9: 501429.74 | G9: 513924.39 | H9: 523842.69 | I9: 539652.26 | J9: =SUM(F9:I9) -> 2078849.1 | K9: 550743.69 | L9: 557909.87 | M9: 554791.23 | N9: 549643.71 | O9: =SUM(K9:N9) -> 2213088.5 | P9: 571305.21
B10: Cost of revenues | F10: 270795.77 | G10: 281260.56 | H10: 294461.23 | I10: 366770.25 | J10: =SUM(F10:I10) -> 1213287.8 | K10: 299929.35 | L10: 328352.85 | M10: 335206.55 | N10: 378291.2 | O10: =SUM(K10:N10) -> 1341780 | P10: 336253.75
B11: Marketing | F11: 35875.84 | G11: 42278.11 | H11: 44516.36 | I11: 55489.91 | J11: =SUM(F11:I11) -> 178160.22 | K11: 38918.46 | L11: 40247.2 | M11: 39756.78 | N11: 58212.7 | O11: =SUM(K11:N11) -> 177135.14 | P11: 38875.34
B12: Technology and development | F12: 36764.49 | G12: 37612.47 | H12: 39472.09 | I12: 45322.9 | J12: =SUM(F12:I12) -> 159171.95 | K12: 46027.1 | L12: 50179.22 | M12: 46391.73 | N12: 47174.82 | O12: =SUM(K12:N12) -> 189772.87 | P12: 48109.25
B13: General and administrative | F13: 20803.72 | G13: 23439.15 | H13: 22525.3 | I13: 27845.3 | J13: =SUM(F13:I13) -> 94613.47 | K13: 27854.96 | L13: 28650.79 | M13: 26124.91 | N13: 27471.71 | O13: =SUM(K13:N13) -> 110102.37 | P13: 28064.68
A14: Operating income | F14: =F9-SUM(F10:F13) -> 137189.92 | G14: =G9-SUM(G10:G13) -> 129334.1 | H14: =H9-SUM(H10:H13) -> 122867.71 | I14: =I9-SUM(I10:I13) -> 44223.9 | J14: =SUM(F14:I14) -> 433615.63 | K14: =K9-SUM(K10:K13) -> 138013.82 | L14: =L9-SUM(L10:L13) -> 110479.81 | M14: =M9-SUM(M10:M13) -> 107311.26 | N14: =N9-SUM(N10:N13) -> 38493.28 | O14: =O9-SUM(O10:O13) -> 394298.17 | P14: =P9-SUM(P10:P13) -> 120002.19
A15: Other income (expense):
B16: Interest expense | F16: -13610.8 | G16: -13392.54 | H16: -13330.03 | I16: -13260.03 | J16: =SUM(F16:I16) -> -53593.4 | K16: -13130.53 | L16: -12281.85 | M16: -12080.25 | N16: -11942.21 | O16: =SUM(K16:N16) -> -49434.84 | P16: -12196.73
B17: Interest and other income (expense) | F17: 18836.02 | G17: -4376.33 | H17: 6729.45 | I17: 7595.84 | J17: =SUM(F17:I17) -> 28784.98 | K17: 13695.15 | L17: 15415.82 | M17: 18298.28 | N17: -23797.55 | O17: =SUM(K17:N17) -> 23611.7 | P17: -4984.28
A18: Income before income taxes | F18: =SUM(F14:F17) -> 142415.14 | G18: =SUM(G14:G17) -> 111565.23 | H18: =SUM(H14:H17) -> 116267.13 | I18: =SUM(I14:I17) -> 38559.71 | J18: =SUM(F18:I18) -> 408807.21 | K18: =SUM(K14:K17) -> 138578.44 | L18: =SUM(L14:L17) -> 113613.78 | M18: =SUM(M14:M17) -> 113529.29 | N18: =SUM(N14:N17) -> 2753.52 | O18: =SUM(O14:O17) -> 368475.03 | P18: =SUM(P14:P17) -> 102821.18
A19: Benefit from (provision for) income taxes | F19: -22945.09 | G19: -16854.32 | H19: -14832.16 | I19: 3960.32 | J19: =SUM(F19:I19) -> -50671.25 | K19: -26757.15 | L19: -12747.21 | M19: -15652.35 | N19: 1116.36 | O19: =SUM(K19:N19) -> -54040.35 | P19: -802.3946
A20: Net income | F20: =F18+F19 -> 119470.05 | G20: =G18+G19 -> 94710.91 | H20: =H18+H19 -> 101434.97 | I20: =I18+I19 -> 42520.03 | J20: =SUM(F20:I20) -> 358135.96 | K20: =K18+K19 -> 111821.29 | L20: =L18+L19 -> 100866.57 | M20: =M18+M19 -> 97876.94 | N20: =N18+N19 -> 3869.88 | O20: =O18+O19 -> 314434.68 | P20: =P18+P19 -> 102018.79
A21: Earnings per share:
B22: Basic | F22: =F20/F25 -> 3.8506827 | G22: =G20/G25 -> 3.0531096 | H22: =H20/H25 -> 3.2726807 | I22: =I20/I25 -> 1.3697431 | J22: =SUM(F22:I22) -> 11.546216 | K22: =K20/K25 -> 3.5966709 | L22: =L20/L25 -> 3.2413189 | M22: =M20/M25 -> 3.1429785 | N22: =N20/N25 -> 0.1241779 | O22: =SUM(K22:N22) -> 10.105146 | P22: =P20/P25 -> 3.2732866
B23: Diluted | F23: =F20/F26 -> 3.745745 | G23: =G20/G26 -> 2.9728121 | H23: =H20/H26 -> 3.1852965 | I23: =I20/I26 -> 1.3326803 | J23: =SUM(F23:I23) -> 11.236534 | K23: =K20/K26 -> 3.5264976 | L23: =L20/L26 -> 3.2009112 | M23: =M20/M26 -> 3.104831 | N23: =N20/N26 -> 0.12240479 | O23: =SUM(K23:N23) -> 9.9546446 | P23: =P20/P26 -> 3.2213892
A24: Weighted-average shares of common stock outstanding:
B25: Basic | F25: 31025.68 | G25: 31021.13 | H25: 30994.46 | I25: 31042.34 | J25: =I25 -> 31042.34 | K25: 31090.22 | L25: 31118.99 | M25: 31141.46 | N25: 31164 | O25: =N25 -> 31164 | P25: 31167.08
B26: Diluted | F26: 31894.87 | G26: 31859.03 | H26: 31844.75 | I26: 31905.65 | J26: =I26 -> 31905.65 | K26: 31708.88 | L26: 31511.83 | M26: 31524.08 | N26: 31615.43 | O26: =N26 -> 31615.43 | P26: 31669.19

Sheet Balance Sheet
A1: BigTechCompany
A2: Consolidated Balance Sheets
A3: (unaudited) | J3: 0.07
A4: (in thousands)
G6: March 31, | H6: June 30, | I6: September 30, | J6: December 31, | K6: March 31, | L6: June 30, | M6: September 30, | N6: December 31, | O6: March 31, | P6: June 30, | Q6: September 30, | R6: December 31,
G7: 2021 | H7: 2021 | I7: 2021 | J7: 2021 | K7: 2022 | L7: 2022 | M7: 2022 | N7: 2022 | O7: 2023 | P7: 2022 | Q7: 2022 | R7: 2022
A8: Assets
A9: Current assets:
C10: Cash and cash equivalents | G10: 588259.35 | H10: 544427.1 | I10: 526867.67 | J10: 421946.28 | K10: 420626.22 | L10: 407361.43 | M10: 427961.31 | N10: 360302.32 | O10: 470021.58 | P10: 5819449 | Q10: 6113733 | R10: 5147176
C11: Short-term investments | G11: 0 | H11: 0 | I11: 0 | J11: 0 | K11: 0 | L11: 0 | M11: 0 | N11: 63789.32 | O11: 77903.7 | P11: 0 | Q11: 0 | R11: 911276
C12: Other current assets | G12: 119266.21 | H12: 127872.22 | I12: 132237.42 | J12: 142941.47 | K12: 146234.83 | L12: 141493.03 | M12: 189221.9 | N12: 224561.47 | O12: 185858.33 | P12: 2021329 | Q12: 2703170 | R12: 3208021
F13: Total current assets | G13: =SUM(G10:G12) -> 707525.56 | H13: =SUM(H10:H12) -> 672299.32 | I13: =SUM(I10:I12) -> 659105.09 | J13: =SUM(J10:J12) -> 564887.75 | K13: =SUM(K10:K12) -> 566861.05 | L13: =SUM(L10:L12) -> 548854.46 | M13: =SUM(M10:M12) -> 617183.21 | N13: =SUM(N10:N12) -> 648653.11 | ... R13: =SUM(R10:R12) -> 9266473
A14: Content assets, net | G14: 1823079.4 | H14: 1910414.8 | I14: 2028183.2 | J14: 2164367.7 | K14: 2183434.4 | L14: 2277323.9 | M14: 2294413.8 | N14: 2291569.9 | O14: 2264442.9 | P14: 32533199 | Q14: 32777340 | R14: 32736713
A15: Property and equipment, net | G15: 71079.33 | H15: 77520.59 | I15: 85407.98 | J15: 92641.71 | K15: 96863.41 | L15: 95334.4 | M15: 96092.78 | N15: 97877.99 | O15: 98916.58 | P15: 1361920 | Q15: 1372754 | R15: 1398257
A16: Other non-current assets | G16: 206926.72 | H16: 207733.12 | I16: 219093.77 | J16: 299029.22 | K16: 326004.42 | L16: 323052.66 | M16: 321663.3 | N16: 363532.75 | O16: 367181.08 | P16: 4615038 | Q16: 4595190 | R16: 5193325
F17: Total assets | G17: =SUM(G13:G16) -> 2808611 | H17: =SUM(H13:H16) -> 2867967.8 | I17: =SUM(I13:I16) -> 2991790 | J17: =SUM(J13:J16) -> 3120926.4 | K17: =SUM(K13:K16) -> 3173163.3 | L17: =SUM(L13:L16) -> 3244565.5 | M17: =SUM(M13:M16) -> 3329353.1 | N17: =SUM(N13:N16) -> 3401633.8 | ... R17: =SUM(R13:R16) -> 48594768
A18: Liabilities and Stockholders' Equity
A19: Current liabilities:
C20: Current content liabilities | G20: 300856.99 | H20: 293851.18 | I20: 287767.34 | J20: 300507.69 | K20: 284640.23 | L20: 292247.62 | M20: 295812.3 | N20: 313610.5 | O20: 304120.6 | P20: 4174966 | Q20: 4225890 | R20: 4480150
C21: Accounts payable | G21: 37305.94 | H21: 43605.17 | I21: 45014.13 | J21: 58623.81 | K21: 43204.14 | L21: 35299.46 | M21: 39210.92 | N21: 47005.91 | O21: 41439.09 | P21: 504278 | Q21: 560156 | R21: 671513
C22: Accrued expenses and other liabilities | G22: 90426.84 | H22: 78791.37 | I22: 98918.4 | J22: 101454.57 | K22: 127198.19 | L22: 111722.45 | M22: 126248.85 | N22: 106025.5 | O22: 120264.83 | P22: 1596035 | Q22: 1803555 | R22: 1514650
C23: Deferred revenue | G23: 79818.97 | H23: 83115.48 | I23: 82784.24 | J23: 84653.94 | K23: 86733.36 | L23: 85732.01 | M23: 82342.61 | N23: 88526.27 | O23: 88358.97 | P23: 1224743 | Q23: 1176323 | R23: 1264661
C24: Short-term debt | G24: 48915.16 | H24: 48938.96 | I24: 48963.11 | J24: 48987.61 | K24: 0 | L24: 0 | M24: 0 | N24: 0 | O24: 27941.41 | P24: 0 | Q24: 0 | R24: 0
F25: Total current liabilities | G25: =SUM(G20:G24) -> 557323.9 | H25: =SUM(H20:H24) -> 548302.16 | I25: =SUM(I20:I24) -> 563447.22 | J25: =SUM(J20:J24) -> 594227.62 | K25: =SUM(K20:K24) -> 541775.92 | L25: =SUM(L20:L24) -> 525001.54 | M25: =SUM(M20:M24) -> 543614.68 | N25: =SUM(N20:N24) -> 555168.18 | ... R25: =SUM(R20:R24) -> 7930974
A26: Non-current content liabilities | G26: 172593.82 | H26: 158570.02 | I26: 161071.82 | J26: 216594.91 | K26: 206165.47 | L26: 209297.27 | M26: 206875.76 | N26: 215689.39 | O26: 203562.03 | P26: 2989961 | Q26: 2955368 | R26: 3081277
A27: Long-term debt | G27: 1040238.6 | H27: 1044882.2 | I27: 1035558.4 | J27: 1028515 | K27: 1017419.3 | L27: 996331.21 | M27: 972168.19 | N27: 1004715.3 | O27: 982657.55 | P27: 14233303 | Q27: 13888117 | R27: 14353076
A28: Other non-current liabilities | G28: 136569.02 | H28: 145742.45 | I28: 159689.39 | J28: 172141.48 | K28: 179719.89 | L28: 178617.25 | M28: 169724.59 | N28: 171642.8 | O28: 168005.95 | P28: 2551675 | Q28: 2424637 | R28: 2452040
F29: Total liabilities | G29: =SUM(G25:G28) -> 1906725.4 | H29: =SUM(H25:H28) -> 1897496.9 | I29: =SUM(I25:I28) -> 1919766.8 | J29: =SUM(J25:J28) -> 2011479.1 | K29: =SUM(K25:K28) -> 1945080.6 | L29: =SUM(L25:L28) -> 1909247.3 | M29: =SUM(M25:M28) -> 1892383.2 | N29: =SUM(N25:N28) -> 1947215.7 | O29: =SUM(O25:O28) -> 1936350.4 | P29: 27274961 | Q29: 27034046 | R29: =SUM(R25:R28) -> 27817367
A30: Stockholders' equity:
B31: Common stock | G31: 252005.88 | H31: 260487.22 | I31: 269677.17 | J31: 281719.27 | K31: 290890.6 | L31: 302180.9 | M31: 313177.34 | N31: 324632.07 | O31: 333367.65 | P31: 4316870 | Q31: 4473962 | R31: 4637601
B32: Treasury stock at cost | G32: 0 | H32: -35001.54 | I32: -42001.54 | J32: -57693.3 | K32: -57693.3 | L32: -57693.3 | M32: -57693.3 | N32: -57693.3 | O32: -86024.4 | P32: -824190 | Q32: -824190 | R32: -824190
B33: Accumulated other comprehensive income (loss) | G33: 289.59 | H33: 684.25 | I33: -1388.45 | J33: -2834.65 | K33: -5191.9 | L33: -10113.32 | M33: -17335.01 | N33: -15211.42 | O33: -13418.65 | P33: -144476 | Q33: -247643 | R33: -217306
B34: Retained earnings | G34: 649590.13 | H34: 744301.04 | I34: 845736.01 | J34: 888256.04 | K34: 1000077.3 | L34: 1100943.9 | M34: 1198820.8 | N34: 1202690.7 | O34: 1294049.1 | P34: 15727770 | Q34: 17126012 | R34: 17181296
F35: Total stockholders' equity | G35: =SUM(G31:G34) -> 901885.6 | H35: =SUM(H31:H34) -> 970470.97 | I35: =SUM(I31:I34) -> 1072023.2 | J35: =SUM(J31:J34) -> 1109447.4 | K35: =SUM(K31:K34) -> 1228082.7 | L35: =SUM(L31:L34) -> 1335318.2 | M35: =SUM(M31:M34) -> 1436969.9 | N35: =SUM(N31:N34) -> 1454418.1 | ... R35: =SUM(R31:R34) -> 20777401
F36: Total liabilities and stockholders' equity | G36: =G29+G35 -> 2808611 | H36: =H29+H35 -> 2867967.8 | I36: =I29+I35 -> 2991790 | J36: =J29+J35 -> 3120926.4 | K36: =K29+K35 -> 3173163.3 | L36: =L29+L35 -> 3244565.5 | M36: =M29+M35 -> 3329353.1 | N36: =N29+N35 -> 3401633.8 | ... R36: =R29+R35 -> 48594768

Sheet Cash Flows
A1: BigTechCompany
A2: Consolidated Statements of Cash Flows
A3: (unaudited)
A4: (in thousands)
H5: Three Months Ended | L5: Twelve Months Ended | M5: Three Months Ended | Q5: Twelve Months Ended | R5: Three Months Ended
H6: March 31, | I6: June 30, | J6: September 30, | K6: December 31, | L6: December 31, | M6: March 31, | N6: June 30, | O6: September 30, | P6: December 31, | Q6: December 31, | R6: March 31,
H7: 2021 | I7: 2021 | J7: 2021 | K7: 2021 | L7: 2021 | M7: 2022 | N7: 2022 | O7: 2022 | P7: 2022 | Q7: 2022 | R7: 2023
A8: Cash flows from operating activities:
B9: Net income | H9: 119470.05 | I9: 94710.91 | J9: 101434.97 | K9: 42520.03 | L9: =SUM(H9:K9) -> 358135.96 | M9: 111821.29 | N9: 100866.57 | O9: 97876.94 | P9: 3869.88 | Q9: =SUM(M9:P9) -> 314434.68 | R9: ='[1]Income Statement'!P20 -> 0
B10: Adjustments to reconcile net income to net cash | H10: 0 | I10: 0 | J10: 0 | K10: 0 | M10: 0 | N10: 0 | O10: 0 | P10: 0 | R10: 0
C11: provided by (used in) operating activities: | H11: 0 | I11: 0 | J11: 0 | K11: 0 | M11: 0 | N11: 0 | O11: 0 | P11: 0 | R11: 0
D12: Additions to content assets | H12: -229920.32 | I12: -286772.5 | J12: -326636.59 | K12: -395824.73 | L12: =SUM(H12:K12) -> -1239154.1 | M12: -250891.48 | N12: -328090.77 | O12: -320786.97 | P12: -278963.44 | Q12: =SUM(M12:P12) -> -1178732.7 | R12: -172106.62
D13: Change in content liabilities | H13: -18622.8 | I13: -21854.56 | J13: -2047.22 | K13: 58827.44 | L13: =SUM(H13:K13) -> 16302.86 | M13: -24300.43 | N13: 13385.96 | O13: 4260.69 | P13: 19205.48 | Q13: =SUM(M13:P13) -> 12551.7 | R13: -24835.37
D14: Amortization of content assets | H14: 190343.72 | I14: 196476.21 | J14: 207413.57 | K14: 261892.19 | L14: =SUM(H14:K14) -> 856125.69 | M14: 221645.55 | N14: 228294.36 | O14: 255751.44 | P14: 276137.89 | Q14: =SUM(M14:P14) -> 981829.24 | R14: 242198.88
D15: Depreciation and amortization of property, equipment and intangibles | H15: 2501.87 | I15: 2690.38 | J15: 4917.71 | K15: 4478.88 | L15: =SUM(H15:K15) -> 14588.84 | M15: 5222.14 | N15: 5845.35 | O15: 5963.16 | P15: 6537.09 | Q15: =SUM(M15:P15) -> 23567.74 | R15: 6323.45
D16: Stock-based compensation expense | H16: 7506.1 | I16: 7110.81 | J16: 6655.46 | K16: 6953.03 | L16: =SUM(H16:K16) -> 28225.4 | M16: 8344.63 | N16: 10527.44 | O16: 10644.34 | P16: 10765.23 | Q16: =SUM(M16:P16) -> 40281.64 | R16: 6936.93
D17: Foreign currency remeasurement loss (gain) on debt | H17: -17733.1 | I17: 4415.18 | J17: -9554.16 | K17: -7274.19 | L17: =SUM(H17:K17) -> -30146.27 | M17: -11327.47 | N17: -21315.91 | O17: -24392.06 | P17: 32317.67 | Q17: =SUM(M17:P17) -> -24717.77 | R17: 5645.57
D18: Other non-cash items | H18: 5085.99 | I18: 7567.21 | J18: 7154.77 | K18: 6566.42 | L18: =SUM(H18:K18) -> 26374.39 | M18: 7137.76 | N18: 14376.18 | O18: 7175.91 | P18: 8658.16 | Q18: =SUM(M18:P18) -> 37348.01 | R18: 8400.56
D19: Deferred income taxes | H19: 11181.31 | I19: 3578.89 | J19: 3567.69 | K19: -4359.53 | L19: =SUM(H19:K19) -> 13968.36 | M19: -4823.42 | N19: -8107.4 | O19: -4045.79 | P19: 5318.11 | Q19: =SUM(M19:P19) -> -11658.5 | R19: -6914.74
D20: Changes in operating assets and liabilities: | H20: 0 | I20: 0 | J20: 0 | K20: 0 | M20: 0 | N20: 0 | O20: 0 | P20: 0 | R20: 0
E21: Other current assets | H21: -15508.85 | I21: -3666.11 | J21: -6660.15 | K21: -42.56 | L21: =SUM(H21:K21) -> -25877.67 | M21: 2880.99 | N21: 8637.93 | O21: -8404.97 | P21: -27882.33 | Q21: =SUM(M21:P21) -> -24768.38 | R21: -6196.54
E22: Accounts payable | H22: -9611.91 | I22: 5061.91 | J22: 1738.52 | K22: 12969.53 | L22: =SUM(H22:K22) -> 10158.05 | M22: -15081.08 | N22: -8543.36 | O22: 3771.25 | P22: 8755.18 | Q22: =SUM(M22:P22) -> -11098.01 | R22: -6276.76
E23: Accrued expenses and other liabilities | H23: 12452.79 | I23: -12000.1 | J23: 18884.18 | K23: -6713.21 | L23: =SUM(H23:K23) -> 12623.66 | M23: 24553.41 | N23: -16710.33 | O23: 14845.04 | P23: -26574.03 | Q23: =SUM(M23:P23) -> -3885.91 | R23: 12970.93
E24: Deferred revenue | H24: 1559.53 | I24: 3296.51 | J24: -331.24 | K24: 1869.7 | L24: =SUM(H24:K24) -> 6394.5 | M24: 1172.01 | N24: -726.32 | O24: -3389.4 | P24: 4858.63 | Q24: =SUM(M24:P24) -> 1914.92 | R24: -167.3
E25: Other non-current assets and liabilities | H25: -4295.76 | I25: -5078.01 | J25: -770.98 | K25: -10092.18 | L25: =SUM(H25:K25) -> -20236.93 | M25: -11755.17 | N25: 8752.8 | O25: -292.88 | P25: -11933.46 | Q25: =SUM(M25:P25) -> -15228.71 | R25: -4825.59
G26: Net cash provided by (used in) operating activities | H26: =SUM(H9:H25) -> 54408.62 | I26: =SUM(I9:I25) -> -4463.27 | J26: =SUM(J9:J25) -> 5766.53 | K26: =SUM(K9:K25) -> -28229.18 | L26: =SUM(L9:L25) -> 27482.7 | M26: =SUM(M9:M25) -> 64598.73 | N26: =SUM(N9:N25) -> 7192.5 | O26: =SUM(O9:O25) -> 38976.7 | ... R26: =SUM(R9:R25) -> 61153.4
A27: Cash flows from investing activities:
B28: Purchases of property and equipment | H28: -5670.07 | I28: -7719.46 | J28: -11712.89 | K28: -11618.53 | L28: =SUM(H28:K28) -> -36720.95 | M28: -8481.06 | N28: -6301.26 | O28: -5947.2 | P28: -7811.51 | Q28: =SUM(M28:P28) -> -28541.03 | R28: -4341.33
B29: Change in other assets | H29: -323.05 | I29: -70 | J29: -1491.28 | K29: 0 | L29: =SUM(H29:K29) -> -1884.33 | M29: 0 | N29: 0 | O29: 0 | P29: 0 | Q29: =SUM(M29:P29) -> 0 | R29: 0
B30: Acquisitions | H30: 0 | I30: 0 | J30: 0 | K30: -55184.43 | L30: =SUM(H30:K30) -> -55184.43 | M30: -8716.47 | N30: -4821.32 | O30: 0 | P30: -39479.3 | Q30: =SUM(M30:P30) -> -53017.09 | R30: 0
B31: Purchases of short-term investments | H31: 0 | I31: 0 | J31: 0 | K31: 0 | L31: 0 | M31: 0 | N31: 0 | O31: 0 | P31: -63789.32 | Q31: =SUM(M31:P31) -> -63789.32 | R31: -14114.38
G32: Net cash used in investing activities | H32: =SUM(H28:H31) -> -5993.12 | I32: =SUM(I28:I31) -> -7789.46 | J32: =SUM(J28:J31) -> -13204.17 | K32: =SUM(K28:K31) -> -66802.96 | L32: =SUM(L28:L31) -> -93789.71 | M32: =SUM(M28:M31) -> -17197.53 | N32: =SUM(N28:N31) -> -11122.58 | O32: =SUM(O28:O31) -> -5947.2 | ... R32: =SUM(R28:R31) -> -18455.71
A33: Cash flows from financing activities:
B34: Proceeds from issuance of debt | H34: 0 | I34: 0 | J34: 0 | K34: 0 | L34: =SUM(H34:K34) -> 0 | M34: 0 | N34: 0 | O34: 0 | P34: 0 | Q34: =SUM(M34:P34) -> 0 | R34: 0
B35: Debt issuance costs | H35: 0 | I35: 0 | J35: 0 | K35: 0 | L35: =SUM(H35:K35) -> 0 | M35: 0 | N35: 0 | O35: 0 | P35: 0 | Q35: =SUM(M35:P35) -> 0 | R35: 0
B36: Repayments of debt | H36: -500000 | I36: 0 | J36: 0 | K36: 0 | L36: =SUM(H36:K36) -> -500000 | M36: -700000 | N36: 0 | O36: 0 | P36: 0 | Q36: =SUM(M36:P36) -> -700000 | R36: 0
B37: Proceeds from issuance of common stock | H37: 48071 | I37: 19749 | J37: 18445 | K37: 88149 | L37: =SUM(H37:K37) -> 174414 | M37: 13678 | N37: 11250 | O37: 4113 | P37: 6705 | Q37: =SUM(M37:P37) -> 35746 | R37: 26028
B38: Repurchases of common stock | H38: 0 | I38: -500022 | J38: -100000 | K38: 0 | L38: =SUM(H38:K38) -> -600022 | M38: 0 | N38: 0 | O38: 0 | P38: 0 | Q38: =SUM(M38:P38) -> 0 | R38: -400101
B39: Taxes paid related to net share settlement of equity awards | H39: 0 | I39: 0 | J39: 0 | K39: -224168 | L39: =SUM(H39:K39) -> -224168 | M39: 0 | N39: 0 | O39: 0 | P39: 0 | Q39: =SUM(M39:P39) -> 0 | R39: 0
G40: Net cash provided by (used in) financing activities | H40: =SUM(H34:H39) -> -451929 | I40: =SUM(I34:I39) -> -480273 | J40: =SUM(J34:J39) -> -81555 | K40: =SUM(K34:K39) -> -136019 | L40: =SUM(L34:L39) -> -1149776 | M40: =SUM(M34:M39) -> -686322 | N40: =SUM(N34:N39) -> 11250 | O40: =SUM(O34:O39) -> 4113 | ... R40: =SUM(R34:R39) -> -374073
...

Sheet Customer Data
C3: Three Months Ended | G3: Three Months Ended | K3: Three Months Ended
C4: March 31, | D4: June 30, | E4: September 30, | F4: December 31, | G4: March 31, | H4: June 30, | I4: September 30, | J4: December 31, | K4: March 31,
C5: 2021 | D5: 2021 | E5: 2021 | F5: 2021 | G5: 2022 | H5: 2022 | I5: 2022 | J5: 2022 | K5: 2023
B6: Revenue | C6: ='Income Statement'!F9 -> 501429.74 | D6: ='Income Statement'!G9 -> 513924.39 | E6: ='Income Statement'!H9 -> 523842.69 | F6: ='Income Statement'!I9 -> 539652.26 | G6: ='Income Statement'!K9 -> 550743.69 | H6: ='Income Statement'!L9 -> 557909.87 | I6: ='Income Statement'!M9 -> 554791.23 | J6: ='Income Statement'!N9 -> 549643.71 | K6: ='Income Statement'!P9 -> 571305.21
B7: Quarterly Subscription Cost | C7: 33 | D7: 33 | E7: 33 | F7: 33 | G7: 34 | H7: 34 | I7: 34 | J7: 34 | K7: 34
B9: Users (Beginning of Period) | C9: =C6/C7 -> 15194.841 | D9: =D6/D7 -> 15573.466 | E9: =E6/E7 -> 15874.021 | F9: =F6/F7 -> 16353.099 | G9: =G6/G7 -> 16198.344 | H9: =H6/H7 -> 16409.114 | I9: =I6/I7 -> 16317.389 | J9: =J6/J7 -> 16165.991 | K9: =K6/K7 -> 16803.094
B10: New users | C10: =C13+C11 -> 467.62576 | D10: =D13+D11 -> 500.55455 | E10: =E13+E11 -> 683.07788 | F10: =F13+F11 -> 289.24504 | G10: =G13+G11 -> 2656.77 | H10: =H13+H11 -> 4908.2753 | I10: =I13+I11 -> 1503.6024 | J10: =J13+J11 -> 1881.1029 | K10: =K13+K11 -> 1964.9056
B11: Users who canceled | C11: 89 | D11: 200 | E11: 204 | F11: 444 | G11: 2446 | H11: 5000 | I11: 1655 | J11: 1244 | K11: 322
B12: Users (End of Period) | C12: =D9 -> 15573.466 | D12: =E9 -> 15874.021 | E12: =F9 -> 16353.099 | F12: =G9 -> 16198.344 | G12: =H9 -> 16409.114 | H12: =I9 -> 16317.389 | I12: =J9 -> 16165.991 | J12: =K9 -> 16803.094 | K12: 18446
B13: Change in users | C13: =C12-C9 -> 378.62576 | D13: =D12-D9 -> 300.55455 | E13: =E12-E9 -> 479.07788 | F13: =F12-F9 -> -154.75496 | G13: =G12-G9 -> 210.77 | H13: =H12-H9 -> -91.724706 | I13: =I12-I9 -> -151.39765 | J13: =J12-J9 -> 637.10294 | K13: =K12-K9 -> 1642.9056
B15: Churn rate | D15: =D11/D9 -> 0.012842356 | E15: =E11/E9 -> 0.012851186 | F15: =F11/F9 -> 0.027150817 | G15: =G11/G9 -> 0.15100309 | H15: =H11/H9 -> 0.30470872 | I15: =I11/I9 -> 0.10142554 | J15: =J11/J9 -> 0.076951667 | K15: =K11/K9 -> 0.019163137 | M15: Hint: # of customers
